---
title: "Go学习笔记 11"
date: 2021-05-06T11:17:59+08:00
draft: false
description: "Go学习笔记-11"
keywords: ["Function","Defer","Panic","Recover"]
tags: ["Go","教程"]
categories: ["技术","笔记"]
---

在 **Go** 中有一些不常见的流程控制机制：*defer* 、panic、以及 *recover*。由于这些内容与函数紧密相关，所以本篇是[上篇](/post/go/go学习笔记-10)的续。除此之外，也会涉及 *Error*、*for...range* 等一些内容。由于本人水平有限，本篇不会讨论 **Go** 的异常处理机制等问题。

<!--more-->

## 1. Deferred Function Call

**Defferred Function Call** ，即延迟函数调用。我的理解就是把函数调用存入一个数据结构里，准确的说是栈，当所在函数即将要 *return* 时，则会将栈里存储的延迟函数依次调用执行，即使函数由 panic 导致的函数中断退出，栈里存储的函数依旧不被影响正常的执行。

*Defer* 常见的用法是资源清理释放，例如文件打开关闭操作、或网络连接的断开，以及资源锁的锁定释放。

```go
// 文件操作
func CopyFile(destName, srcName string) (written int64, err error) {
    src, err := os.Open(srcName)
    if err != nil {
        return
    }
    defer src.Close()
    dest, err := os.Create(destName)
  if err != nil {
        return
  }
    defer dest.Close()
    return io.Copy(dest, src)
}
// 网络连接
func Download(fileName, url string) (size int64, err error){
    file, err := os.Create(fileName)
    if err !=nil {
        return
    }
    defer file.Close()
    resp, err := http.Get(url)
    if err != nil {
        return
    }
    defer resp.Close()
  	return io.Copy(file, resp)
}
// 资源的锁定释放
var mu sync.Mutex
var counts = make(map[string]int)

func lookup(key string) int{
  mu.Lock()
  defer mu.Unlock()
  return counts[key]
}
```

*Defer* 声明及语法格式很简单，但有三点值得注意。

1. 延迟的函数调用是以先进后出的顺序执行。

   ```go
   package main
   
   import (
   	"fmt"
   )
   
   func trace(s string) {
   	fmt.Println("entering", s)
   }
   func untrace(s string) {
   	fmt.Println("leaving", s)
   }
   
   func track() {
   	country := "China"
   	defer untrace(country)
   	trace(country)
   	state := "Beijing"
   	defer untrace(state)
   	trace(state)
   }
   
   func main() {
   	track()
   }
   ```

   上面例子的输出结果请点击[这里](https://play.golang.org/p/NQ-_YDhMH09)

2. defer将语句入到栈中时，也会将相关的值拷贝同时入栈

   下面的这个例子，当每次循环执行 *defer* 语句时，*i* 表达式的值都会计算出来并一起压入栈，所以输出结果是：3，2，1，0

   ```go
   package main
   
   import (
   	"fmt"
   )
   
   func main() {
   	for i := 0; i < 4; i++ {
   		defer fmt.Println(i)
   	}
   }
   ```

3. 延迟的函数能读取函数的命名返回值结果，并且在 *return* 前能修改更新它。

   ```go
   package main
   
   import (
   	"fmt"
   )
   
   func double(x int) (result int) {
   	defer func() {
   		fmt.Printf("double(%d) =%d \n", x, result)
   	}()
   	return x + x
   }
   
   func main() {
   	x := 2
   	fmt.Printf("%d double result is %d\n", x, double(x))
   }
   ```

   所以，上面的例子输出结果如下：

   ```output
   double(2) =4 
   2 double result is 4
   ```

   请注意，这里的 *result* 不是参数，所以不能适用规则2。那到底是什么原因导致的呢？没错，就是**闭包**。

   如果将上面的例子稍微修改下，结果会变么？

   ```go
   package main
   
   import (
   	"fmt"
   )
   
   func double(x int) int {
   	var result int
   	defer func() {
   		result = x + x
   		fmt.Printf("double(%d) =%d \n", x, result)
   	}()
   	return result
   }
   
   func main() {
   	x := 2
   	fmt.Printf("%d double result is %d\n", x, double(x))
   }
   ```

   上面的例子结果如下：

   ```output
   double(2) =4 
   2 double result is 0
   ```

   结果为什么发生了变化呢？我自己的理解是，上面例子中返回结果未命名，但编译时会自动生成一个，那么 执行 *return result* 时，则会发生值拷贝，即将 *result* 的值复制自动生成的结果变量中，所以虽然延迟的函数由于闭包更新了 *result* 的值，但实际返回结果变量并未修改（注：这段待求证，需要看下汇编）。

## 2. Panic & Recover

在编程语言中一般都会有异常处理机制，**Go** 也不例外。一般的错误通常在编译阶段就会提前告警，比如语法错误或类型错误，但想数组边界问题或指针为 *nil* 这类问题，只有运行时才会引发。并且这类运行时发生的错误，会导致 *panic* ，程序也会退出。当然 *panic* 我们也可以手动触发，让程序主动退出。

### 2.1 触发Panic

```go
package main

import (
	"fmt"
)

func f(x int) {
	if x == 0 {
		panic("x can not be zero")
	}
	fmt.Printf("f(%d)\n", x)
	defer fmt.Printf("defer %d\n", x)
	f(x - 1)
}

func main() {
	f(3)
}
```

执行上面的代码时，当 * x == 0* 时会主动触发 *panic*，同时程序会主动退出，并打印出相关的错误信息。

```output
f(3)
f(2)
f(1)
defer 1
defer 2
defer 3
panic: x can not be zero
...
```

从上面的结果，我们发现一个[上篇](post/go/go学习笔记-10/)提到的 *defer* 的特性，即使在当前函数内出现 *panic*时延迟的函数也会正常被执行。

### 2.2 Recover

异常发生，有时是需要捕获处理的，比如在处理客户端连接时发生 *panic* ，我们不能让程序直接退出，需要主动断开客户端的连接，否则客户端可能会等待一段时间，所以我们需要从 *panic* 恢复—recover，*Go* 恰好提供了一个内置函数 *recover*，可是程序已经 *panic* 了，从哪儿 *recover* 呢。还记得上面提到的 *defer* 么，没错就是它。

下面是一个简单的例子

```go
package main

import (
	"fmt"
)

func divide(a, b int) (result int, err error) {
	defer func() {
		if p := recover(); p != nil {
			err = fmt.Errorf("divide function occurs error: %v", p)
		}
	}()
	result = a / b
	return
}

func main() {
	if _, err := divide(1, 0); err != nil {
		fmt.Println(err)
	}
}
```

通常不应该对进入 *panic* 的程序做任何处理，但正如前面提到的那样，我们需要从 *panic* 中恢复，并在程序崩溃退出前，清理网络文件等资源。

这里还要注意多个协程间，子协程内的 *panic* 是不能被父协程的 *defer* 捕获的。这个知识点具体内容后续章节会详细介绍下。

参考文章

[5.8 Deferred Function Calls - The Go Programming Language](https://www.oreilly.com/library/view/the-go-programming/9780134190570/ebook_split_049.html)

[5.9 Panic - The Go Programming Language](https://www.oreilly.com/library/view/the-go-programming/9780134190570/ebook_split_050.html)

[5.10 Recover - The Go Programming Language](https://www.oreilly.com/library/view/the-go-programming/9780134190570/ebook_split_051.html)

[Defer, Panic, and Recover - The Go Blog](https://blog.golang.org/defer-panic-and-recover)